Workbook

Sheet Combined, overhead
A1: Base overnight cost
B2: 1999 | C2: 2000 | D2: 2001 | E2: 2002 | F2: 2003 | G2: 2004 | H2: 2005 | I2: 2006 | J2: 2007 | K2: 2008 | L2: 2009 | M2: 2010 | N2: 2011 | O2: 2012 | P2: 2013 | Q2: 2014 | R2: 2015 | S2: 2016 | T2: 2017 | U2: 2018 | V2: 2019 | W2: 2020 | X2: 2021 | Y2: 2022
A3: Scrubbed Coal New | B3: 1093 | C3: 1102 | D3: 1021 | Q3: 2734 | R3: 2726
A4: Integrated Coal- Gasification Comb Cycle (IGCC) | B4: 1091 | C4: 1315 | D4: 1220 | Q4: 3525 | R4: 3483
A5: Conv Gas/Oil Comb Cycle | B5: 445 | C5: 449 | D5: 424 | Q5: 871 | R5: 869 | S5: 956 | T5: 923 | U5: 935 | V5: 952
A6: Combined-cycle—single shaft | W6: 1079 | X6: 1082 | Y6: 1201
A7: Adv Gas/Oil Comb Cycle (CC) | B7: 405 | C7: 580 | D7: 533 | Q7: 945 | R7: 942 | S7: 1080 | T7: 1013 | U7: 1026 | V7: 736
A8: Combined-cycle—multi shaft | W8: 954 | X8: 957 | Y8: 1062
A9: Conv Comb Turbine | B9: 329 | C9: 332 | D9: 315 | Q9: 924 | R9: 922 | S9: 1077 | T9: 1040 | U9: 1054 | V9: 1072
A10: Combustion turbine— aeroderivative8 | W10: 1170 | X10: 1169 | Y10: 1294
A11: Adv Comb Turbine | B11: 325 | C11: 465 | D11: 440 | Q11: 641 | R11: 639 | S11: 664 | T11: 640 | U11: 648 | V11: 658
A12: Combustion turbine—industrial frame | W12: 710 | X12: 709 | Y12: 785
A13: Adv Nuclear | B13: 1570 | C13: 2390 | D13: 1.729 | Q13: 4763 | R13: 4646 | S13: 6108 | T13: 5091 | U13: 5148 | V13: 5224 | W13: 6016 | X13: 6034 | Y13: 6695
A14: Conventional Hydropower | Q14: 2213 | R14: 2410 | S14: 2411 | T14: 2220 | U14: 2634 | V14: 2680 | W14: 2752 | X14: 2769 | Y14: 3083
A15: Wind | B15: 776 | C15: 993 | D15: 919 | Q15: 2061 | R15: 1850 | S15: 1644 | T15: 1576 | U15: 1548 | V15: 1518 | W15: 1319 | X15: 1846 | Y15: 1718
A16: Wind Offshore | Q16: 4503 | R16: 4476 | S16: 6331 | T16: 4648 | U16: 4694 | V16: 4758 | W16: 4356 | X16: 4362 | Y16: 4833
A17: Solar Thermal | B17: 1907 | C17: 3059 | D17: 2394 | Q17: 4715 | R17: 3787 | S17: 4168 | T17: 3908 | U17: 3952 | V17: 4011 | W17: 7191 | X17: 7116 | Y17: 7895
A18: Photovoltaic | B18: 2903 | C18: 4836 | D18: 3681 | Q18: 3394 | R18: 3123 | S18: 2480 | T18: 2169 | U18: 1763 | V18: 1876
A19: Photovoltaic tilting | U19: 2004 | V19: 1698 | W19: 1331 | X19: 1248 | Y19: 1327
A20: Solar PV with storage | X20: 1612 | Y20: 1748

Sheet Combined, O&M
A1: Fixed O&M cost
B2: 1999 | C2: 2000 | D2: 2001 | E2: 2002 | F2: 2003 | G2: 2004 | H2: 2005 | I2: 2006 | J2: 2007 | K2: 2008 | L2: 2009 | M2: 2010 | N2: 2011 | O2: 2012 | P2: 2013 | Q2: 2014 | R2: 2015 | S2: 2016 | T2: 2017 | U2: 2018 | V2: 2019 | W2: 2020 | X2: 2021 | Y2: 2022
A3: Scrubbed Coal New | B3: 23.03 | C3: 23.03 | Q3: 31.18 | R3: 31.16
A4: Integrated Coal- Gasification Comb Cycle (IGCC) | B4: 32.13 | C4: 32.13 | Q4: 51.39 | R4: 51.37
A5: Conv Gas/Oil Comb Cycle | B5: 15.35 | C5: 15.35 | Q5: 13.17 | R5: 13.16 | S5: 10.76 | T5: 10.93 | U5: 11.11 | V5: 11.33
A6: Combined-cycle—single shaft | W6: 14.04 | X6: 14.17 | Y6: 14.76
A7: Adv Gas/Oil Comb Cycle (CC) | B7: 14.23 | C7: 14.23 | Q7: 15.37 | R7: 15.36 | S7: 9.78 | T7: 9.94 | U7: 10.1 | V7: 10.3
A8: Combined-cycle—multi shaft | W8: 12.15 | X8: 12.26 | Y8: 12.77
A9: Conv Comb Turbine | B9: 6.35 | C9: 6.35 | Q9: 7.34 | R9: 7.34 | S9: 17.12 | T9: 17.39 | U9: 17.67 | V9: 18.03
A10: Combustion turbine— aeroderivative8 | W10: 16.23 | X10: 16.38 | Y10: 17.06
A11: Adv Comb Turbine | B11: 9.01 | C11: 9.01 | Q11: 7.04 | R11: 7.04 | S11: 6.65 | T11: 6.76 | U11: 6.87 | V11: 7.01
A12: Combustion turbine—industrial frame | W12: 6.97 | X12: 7.04 | Y12: 7.33
A13: Adv Nuclear | B13: 56.29 | C13: 56.29 | Q13: 93.28 | R13: 93.23 | S13: 98.11 | T13: 99.65 | U13: 101.28 | V13: 103.31 | W13: 121.13 | X13: 122.26 | Y13: 127.35
A14: Conventional Hydropower | Q14: 14.83 | R14: 15.15 | S14: 14.7 | T14: 14.93 | U14: 40.05 | V14: 40.85 | W14: 41.63 | X14: 42.01 | Y14: 43.78
A15: Wind | B15: 25.92 | C15: 25.92 | Q15: 39.55 | R15: 39.53 | S15: 45.98 | T15: 46.71 | U15: 47.47 | V15: 48.42 | W15: 26.22 | X15: 26.47 | Y15: 27.57
A16: Wind Offshore | Q16: 74 | R16: 73.96 | S16: 76.1 | T16: 77.3 | U16: 78.56 | V16: 80.14 | W16: 109.54 | X16: 110.56 | Y16: 115.16
A17: Solar Thermal | B17: 46.58 | C17: 46.58 | Q17: 67.26 | R17: 67.23 | S17: 69.17 | T17: 70.26 | U17: 71.41 | V17: 72.84 | W17: 85.03 | X17: 85.82 | Y17: 89.39
A18: Photovoltaic | B18: 9.82 | C18: 9.82 | Q18: 24.69 | R18: 24.68 | S18: 21.33 | T18: 21.66 | U18: 22.02 | V18: 22.46 | W18: 15.19
A19: Solar PV with storage | X19: 15.33 | Y19: 15.97
X20: 32.33 | Y20: 33.67
A26: Price year
B27: 1997 | C27: 1998

Sheet 2000
A1: Table 38. Cost and Performance Characteristics of New Electricity Generating Technologies
A2: Total Overnight Contingency Factors Cost Overnight including Variable Heatrate Heatrate Costs Contingencies O&M4 Fixed in in Online Size Leadtimes in 2001 in 20013 ($2000 O&M4 2001 2010 Technology Years1 (mW) (Years) ($2000/kW) (2000 $/kW) mills/kWh) ($2000/kW) (Btu/kWhr) (Btu/kWr)
A3: Conventional Pulverized Coal | C3: 2005 | D3: 400 | F3: 4 | G3: 1046 | I3: 1.07 | M3: 1 | O3: 1119 | Q3: 3.38 | S3: 23.41 | T3: 9386 | V3: 9087
A4: Integrated Coal- Gasification Combined | C4: 2005 | D4: 428 | F4: 4 | G4: 1250 | I4: 1.07 | M4: 1 | O4: 1338 | Q4: 0.8 | S4: 32.67 | T4: 7869 | V4: 6968
A5: Cycle Conventional Gas/Oil Combined Cycle | C5: 2004 | D5: 250 | F5: 3 | G5: 435 | I5: 1.05 | M5: 1 | O5: 456 | Q5: 0.52 | S5: 15.61 | T5: 7618 | V5: 7000
A6: Adv Gas/Oil Combined Cycle | C6: 2004 | D6: 400 | F6: 3 | G6: 546 | I6: 1.08 | M6: 1 | O6: 590 | Q6: 0.52 | S6: 14.46 | T6: 6870 | V6: 6350
A7: Conv Combustion Turbine5 | C7: 2002 | D7: 160 | F7: 2 | G7: 323 | I7: 1.05 | M7: 1 | O7: 339 | Q7: 0.1 | S7: 6.45 | T7: 11380 | V7: 10600
A8: Adv Combustion Turbine | C8: 2003 | D8: 120 | F8: 2 | G8: 451 | I8: 1.05 | M8: 1 | O8: 474 | Q8: 0.1 | S8: 9.16 | T8: 9020 | V8: 8000
A9: Fuel Cells | C9: 2004 | D9: 10 | F9: 3 | G9: 1810 | I9: 1.05 | M9: 1.1 | O9: 2091 | Q9: 2.08 | S9: 14.98 | T9: 5744 | V9: 5361
A10: Advanced Nuclear | C10: 2005 | D10: 600 | F10: 4 | G10: 1772 | I10: 1.1 | M10: 1.1 | O10: 2144 | Q10: 0.42 | S10: 57.23 | T10: 10400 | V10: 10400
A11: Generic Distributed Generation6 - Base Generic Distributed Generation6 - Peak
A12: 2004 | H12: 2 | K12: 3 | L12: 593 | N12: 1.05 | P12: 1 | R12: 623 | U12: 15.11 | W12: 4.02 | Y12: 10991 | AA12: 9210
A13: 2003 | H13: 1 | K13: 2 | L13: 533 | N13: 1.05 | P13: 1 | R13: 559 | U13: 23.1 | W13: 12.56 | Y13: 10620 | AA13: 10500
A14: Biomass | B14: 2005 | D14: 100 | F14: 4 | G14: 1536 | J14: 1.07 | M14: 1.05 | O14: 1725 | Q14: 2.9 | S14: 44.95 | T14: 8911 | V14: 8911
A15: MSW - Landfill Gas | B15: 2004 | D15: 30 | F15: 3 | G15: 1336 | J15: 1.07 | M15: 1 | O15: 1429 | Q15: 0.01 | S15: 96.31 | T15: 13648 | V15: 13648
A16: Geothermal 7,8 | B16: 2006 | D16: 50 | F16: 4 | G16: 1663 | J16: 1.05 | M16: 1 | O16: 1746 | Q16: 0 | S16: 70.07 | T16: 32173 | V16: 32173
A17: Wind | B17: 2004 | D17: 50 | F17: 3 | G17: 918 | J17: 1.07 | M17: 1 | O17: 982 | Q17: 0 | S17: 25.54 | T17: 10280 | V17: 10280
A18: Solar Thermal8 | B18: 2004 | D18: 100 | F18: 3 | G18: 2157 | J18: 1.07 | M18: 1.1 | O18: 2539 | Q18: 0 | S18: 47.87 | T18: 10280 | V18: 10280
A19: Solar Photovoltaic8 | B19: 2003 | D19: 5 | F19: 2 | G19: 3317 | J19: 1.05 | M19: 1.1 | O19: 3831 | Q19: 0 | S19: 9.85 | T19: 10280 | V19: 10280
A20: 1Online year represents the first year that a new unit could be completed, given an order date of 2001. 2The technological optimism factor is applied to the first four units of a new, unproven design. It reflects the demonstrated tendency to underestimate actual costs for a first-of-a-kind unit. 3Overnight capital cost including contingency factors, excluding regional multipliers and learning effects. Interest charges are also excluded. These represent costs of new projects initiated in 2001. 4O&M = Operation and maintenance. 5Combustion turbine units can be built by the model prior to 2003 if necessary to meet a given region’s reserve margin. 6The costs shown here are slightly different from costs shown in Table 41 because of updated adjustments for inflation. The unit size shown here is higher than that shown in Table 41 to reflect the minimum size that can be represented meaningfully in the model. The lead times are also different from those shown in Table 41 because lead times presented here include site acquisition, site preparation, and permitting for plants that are larger in size. 7Because geothermal cost and performance characteristics are specific for each site, the table entries represent the cost of the least expensive plant that could be built in the Northwest Power Pool region, where most of the proposed sites are located. 8Capital costs for geothermal and solar technologies are net of (reduced by) the ten percent investment tax credit.
A21: Source: Values are derived by the Energy Information Administration, Office of Integrated Analysis and Forecasting, from analysis of reports and discussions with various sources from industry, government, and the Department of Energy National Laboratories.
A22: Table 39. Regional Multipliers for Construction of Fossil-Fueled, Nuclear, and Renewable1 Generating Technologies
A23: EMM Region NE, NY | E23: MAAC | I23: STV | N23: MAPP, ECAR, MAIN | S23: SPP
A24: 1.043 | E24: 0.996 | I24: 0.96 | N24: 1.004 | S24: 0.997
A25: EMM Region RA | E25: NWP | I25: FL | N25: CNV | S25: ERCOT
A26: 1.003 | E26: 1.026 | I26: 0.961 | N26: 1.058 | S26: 0.986
A27: 1Regional multipliers are not applied to geothermal technologies because costs are site specific.
A28: Source: Argonne National Laboratory, Cost and Performance Database for Electric Power Generating Technologies..
A29: Technological Optimism and Learning Overnight costs for each technology are calculated as a function of regional construction parameters, project contingency, and technological optimism and learning factors. For each generating technology available for new capacity in a region, the overnight cost used by the model is calculated using the base cost, technological optimism and contingency factors for the technology from Table 38, the regional factors from Table 39, and the learning parameters from Table 40.

Sheet 1999
A1: Table 37. Cost and Performance Characteristics of New Central Station Electricity Generating Technologies
A2: Overnight Overnight Capital Capital Heatrate Heatrate Costs1 Costs1 Variable First- Nth-of-a- O&M Fixed First- Nth- Year Size Leadtime of-a-kind kind (1997 O&M of-a-kind of-a-kind Technology Available (mW) (Year) ($1997/kW) ($1997/kW) Mills/kWhr) ($1997/kW) (Btu/kWhr) (Btu/kWhr)
A3: Scrubbed Coal New | C3: 1997 | D3: 400 | E3: 4 | F3: 1093 | G3: 1093 | H3: 3.33 | I3: 23.03 | K3: 9585 | L3: 9087
A4: Integrated Gas Comb Cycle | C4: 1997 | D4: 428 | E4: 4 | F4: 1606 | G4: 1091 | H4: 0.79 | I4: 32.13 | K4: 8470 | L4: 6968
A5: Gas/Oil Steam Turbine | C5: 1997 | D5: 300 | E5: 2 | F5: 1004 | G5: 1004 | H5: 0.51 | I5: 30.7 | K5: 9500 | L5: 9500
A6: Conv Gas/Oil Comb Cycle | C6: 1997 | D6: 250 | E6: 3 | F6: 445 | G6: 445 | H6: 0.51 | I6: 15.35 | K6: 8030 | L6: 7000
A7: Adv Gas/Oil Comb Cycle | C7: 1997 | D7: 400 | E7: 3 | F7: 575 | G7: 405 | H7: 0.51 | I7: 14.23 | K7: 6985 | L7: 6350
A8: Conv Combustion Turbine | C8: 1998 | D8: 160 | E8: 2 | F8: 329 | G8: 329 | H8: 0.1 | I8: 6.35 | K8: 11900 | L8: 10600
A9: Adv Combustion Turbine | C9: 1997 | D9: 120 | E9: 2 | F9: 461 | G9: 325 | H9: 0.1 | I9: 9.01 | K9: 9700 | L9: 8000
A10: Fuel Cells | C10: 2001 | D10: 10 | E10: 2 | F10: 2146 | G10: 1458 | H10: 2.05 | I10: 14.74 | K10: 6000 | L10: 5361
A11: Advanced Nuclear | C11: 2001 | D11: 600 | E11: 4 | F11: 2371 | G11: 1570 | H11: 0.41 | I11: 56.29 | K11: 10400 | L11: 10400
A12: Biomass | C12: 2001 | D12: 100 | E12: 4 | F12: 2205 | G12: 1448 | H12: 5.32 | I12: 44 | K12: 9224 | L12: 8219
A13: MSW 2 | C13: 1996 | D13: 30 | E13: 1 | F13: N/A | G13: 5892 | H13: 5.532 | I13: 0 | K13: 16000 | L13: 16000
A14: Geothermal 3 | C14: 1997 | D14: 50 | E14: 4 | F14: 1831 | G14: 1831 | H14: 0 | I14: 85.9 | K14: 32391 | L14: N/A
A15: Wind | C15: 1997 | D15: 50 | E15: 3 | F15: 1109 | G15: 776 | H15: 0 | I15: 25.92 | K15: N/A | L15: N/A
A16: Solar Thermal4 ,5 | C16: 1997 | D16: 100 | E16: 3 | F16: 2904 | G16: 1907 | H16: 0 | I16: 46.58 | K16: N/A | L16: N/A
A17: Photovoltaic5 | C17: 1998 | D17: 5 | E17: 2 | F17: 4162 | G17: 2903 | H17: 0 | I17: 9.82 | K17: N/A | L17: N/A
A18: 1Overnight capital cost plus project contingencies, excluding regional multipliers (See Tables 38 and 39). 2Because municipal solid waste (MSW) does not compete with other technologies in the model, these values are used only in calculating the average costs of electricity. 3Because geothermal cost and performance parameters are specific for each of the 51 sites in the database, the Nth-of-a-kind capital cost and heatrate are averages for the capacity built in 2000. 4Solar thermal is assumed to operate economically only in Electricity Market Module regions 2, 5, and 10-13, that is, West of the Mississippi River, because of its requirement for significant direct, normal insolation. 5Capital costs for solar technologies are net of (reduced by) the 10 percent investment tax credit. O&M = Operation and maintenance. Sources: Most values are derived by the Energy Information Administration, Office of Integrated Analysis and Forecasting from analysis of reports and discussions with various sources from industry, government, and the National Laboratories, with the following specific sources — Solar Thermal: California Energy Commission Memorandum, Technology Characterization for ER94, August 6, 1993. Photovoltaic: Technical Assessment Guide-Electric Power Research Institute (EPRI-TAG1993). MSW: EPRI-TAG 1993.

Sheet 2011
A1: Table 8.2 Cost and performance characteristics of new central station electricity generating technologies
E2: Base Overnight Cost in 2010 (2009 $/ kW) | F2: Contingency Factors | H2: Total Overnight Cost in 20104 (2009 $/ kW) | L2: nth-of-a- kind Heatrate (Btu/ kWhr)
A3: Technology | B3: Online Year1 | C3: Size (mW) | D3: Lead time (years) | F3: Project Contin- gency Factor2 | G3: Techno logical Optimism Factor3 | I3: Variable O&M5 (2009 $/MWh) | J3: Fixed O&M (2009$/ kW) | K3: Heatrate6 in 2010 (Btu/ kWhr)
A4: Scrubbed Coal New7 | B4: 2014 | C4: 1300 | D4: 4 | E4: 2,625 | F4: 1.07 | G4: 1 | H4: 2,809 | I4: 4.2 | J4: 29.31 | K4: 8,800 | L4: 8,740
A5: Integrated Coal- Gasification Comb Cycle (IGCC)7 | B5: 2014 | C5: 1200 | D5: 4 | E5: 2,974 | F5: 1.07 | G5: 1 | H5: 3,182 | I5: 6.79 | J5: 58.52 | K5: 8,700 | L5: 7,450
A6: IGCC with carbon sequestration | B6: 2016 | C6: 520 | D6: 4 | E6: 4,797 | F6: 1.07 | G6: 1.03 | H6: 5,287 | I6: 8.83 | J6: 68.47 | K6: 10,700 | L6: 8,307
A7: Conv Gas/Oil Comb Cycle | B7: 2013 | C7: 540 | D7: 3 | E7: 921 | F7: 1.05 | G7: 1 | H7: 967 | I7: 3.37 | J7: 14.22 | K7: 7,050 | L7: 6,800
A8: Adv Gas/Oil Comb Cycle (CC) | B8: 2013 | C8: 400 | D8: 3 | E8: 917 | F8: 1.08 | G8: 1 | H8: 991 | I8: 3.07 | J8: 14.44 | K8: 6,430 | L8: 6,333
A9: Adv CC with carbon sequestration | B9: 2016 | C9: 340 | D9: 3 | E9: 1,813 | F9: 1.08 | G9: 1.04 | H9: 2,036 | I9: 6.37 | J9: 29.89 | K9: 7,525 | L9: 7,493
A10: Conv Comb Turbine8 | B10: 2012 | C10: 85 | D10: 2 | E10: 916 | F10: 1.05 | G10: 1 | H10: 961 | I10: 8.15 | J10: 9.75 | K10: 10,745 | L10: 10,450
A11: Adv Comb Turbine | B11: 2012 | C11: 210 | D11: 2 | E11: 626 | F11: 1.05 | G11: 1 | H11: 658 | I11: 6.9 | J11: 14.52 | K11: 9,750 | L11: 8,550
A12: Fuel Cells | B12: 2013 | C12: 10 | D12: 3 | E12: 5,846 | F12: 1.05 | G12: 1.1 | H12: 6,752 | I12: 0 | J12: 345.8 | K12: 9,500 | L12: 6,960
A13: Adv Nuclear | B13: 2016 | C13: 2236 | D13: 6 | E13: 4,567 | F13: 1.1 | G13: 1.05 | H13: 5,275 | I13: 2 | J13: 87.69 | K13: 10,453 | L13: 10,453
A14: Distributed Generation - Base | B14: 2013 | C14: 2 | D14: 3 | E14: 1,349 | F14: 1.05 | G14: 1 | H14: 1,416 | I14: 7.37 | J14: 16.58 | K14: 9,050 | L14: 8,900
A15: Distributed Generation - Peak | B15: 2012 | C15: 1 | D15: 2 | E15: 1,620 | F15: 1.05 | G15: 1 | H15: 1,701 | I15: 7.37 | J15: 16.58 | K15: 10,069 | L15: 9,880
... A23: Photovoltaic7,10 | B23: 2012 | C23: 150 | D23: 2 | E23: 4,474 | F23: 1.05 | G23: 1 | H23: 4,697 | I23: 0 | J23: 25.73 | K23: 9,854 | L23: 9,854
A24: 1Online year represents the first year that a new unit could be completed, given an order date of 2010. For wind, geothermal and landfill gas, the online year was moved earlier to acknowledge the significant market activity already occuring in anticipation of the expiration of the Production Tax Credit. 2A contingency allowance is defined by the American Association of Cost Engineers as the “specific provision for unforeseeable elements of costs within a defined project scope; particularly important where previous experience has shown that unforeseeable events which will increase costs are likely to occur” 3The technological optimism factor is applied to the first four units of a new, unproven design, it reflects the demonstrated tendency to underestimate actual costs for a first-of-a-kind unit. 4Overnight capital cost including contingency factors, excluding regional multipliers and learning effects. Interest charges are also excluded. These represent costs of new projects initiated in 2010. 5O&M = Operations and maintenance. 6For hydro, wind, and solar technologies, the heatrate shown represents the average heatrate for conventional thermal generation as of 2009. This is used for purposes of calculating primary energy consumption displaced for these resources, and does not imply an estimate of their actual energy conversion efficiency. 7Capital costs are shown before investment tax credits are applied. 8Combustion turbine units can be built by the model prior to 2012 if necessary to meet a given region’s reserve margin. 9Because geothermal and hydro cost and performance characteristics are specific for each site, the table entries represent the cost of the least expensive plant that could be built in the Northwest Power Pool region, where most of the proposed sites are located. 10Costs and capacities are expressed in terms of net AC power available to the grid for the installed capacity. Sources: For the AEO2011 cycle, EIA commissioned an external consultant to develop current cost estimates for utility-scale electric generating plants. This report can be found at http://www.eia.gov/oiaf/beck_plantcosts/index.html. Site specific costs for geothermal were provided by the National Energy Renewable Laboratory, “Updated U.S. Geothermal Supply Curve”, February 2010.

Sheet 2001
A1: Table 43. Cost and Performance Characteristics of New Electricity Generating Technologies
A2: Total Contingency Factors Overnight Cost Overnight including Variable Costs Project Technological contingencies O&M4 Fixed Heatrate in Heatrate in Online Size Leadtimes in 2000 Contingency Optimism in 20003 ($1999 O&M4 2000 2010 Technology Years1 (mW) (Years) ($1999/kW) Factor Factor2 (1999 $/kW) mills/kWh) ($1999/kW) (Btu/kWhr) (Btu/kWhr)
A3: Conventional Pulverized Coal Integrated Coal- Gasification Combined Cycle Conventional Gas/Oil Combined Cycle Adv Gas/Oil Combined Cycle Conv Combustion Turbine5 Adv Combustion Turbine Fuel Cells Advanced Nuclear Generic Distributed Generation6 - Base Generic Distributed Generation6 - Peak Biomass MSW - Landfill Gas Geothermal 7,8 Wind Solar Thermal8 Solar Photovoltaic8 2003 5 2 3,681 1.05 1.10 4,252 0.00 9.85 10,2809 10,2809 1Online year represents the first year that a new unit could be completed, given an order date of 2001. 2The technological optimism factor is applied to the first four units of a new, unproven design, it reflects the demonstrated tendency to underestimate actual costs for a first-of-a-kind unit. 3Overnight capital cost including contingency factors, excluding regional multipliers and learning effects. Interest changes are also excluded. These represent costs of new projects initiated in 2000. 4O&M = Operation and maintenance. 5Combustion turbine units can be built by the model prior to 2003 if necessary to meet a given region’s reserve margin. 6The costs shown here are slightly different from costs shown in Table 45 because of updated adjustments for inflation. The unit size shown here is higher than that shown in Table 45 to reflect the minimum size that can be represented meaningfully in the model. The lead times are also different from those shown in Table 45 because lead times presented here include site acquisition, site preparation, and permitting for plants that are larger in size. 7Because geothermal cost and performance characteristics are specific for each site, the table entries represent the cost of the least expensive plant that could be built in the Northwest Power Pool region, where most of the proposed sites are located. 8Capital costs for geothermal and solar technologies are net of (reduced by) the ten percent investment tax credit. 9Heat rates for solar and wind technologies are fossil-fuel average heat rates.
A5: 2005 | C5: 400 | E5: 4 | F5: 1021 | G5: 1.07 | I5: 1 | J5: 1092 | L5: 3.3 | M5: 22.85 | N5: 9419 | P5: 9087
A6: 2005 | C6: 428 | E6: 4 | F6: 1220 | G6: 1.07 | I6: 1 | J6: 1306 | L6: 0.78 | M6: 31.89 | N6: 7969 | P6: 6968
A7: 2004 | C7: 250 | E7: 3 | F7: 424 | G7: 1.05 | I7: 1 | J7: 445 | L7: 0.51 | M7: 15.24 | N7: 7687 | P7: 7000
A8: 2004 | C8: 400 | E8: 3 | F8: 533 | G8: 1.08 | I8: 1 | J8: 576 | L8: 0.51 | M8: 14.12 | N8: 6927 | P8: 6350
A9: 2003 | C9: 160 | E9: 2 | F9: 315 | G9: 1.05 | I9: 1 | J9: 331 | L9: 0.1 | M9: 6.3 | N9: 11467 | P9: 10600
A10: 2003 | C10: 120 | E10: 2 | F10: 440 | G10: 1.05 | I10: 1 | J10: 462 | L10: 0.1 | M10: 8.94 | N10: 9133 | P10: 8000
A11: 2004 | C11: 10 | E11: 3 | F11: 1767 | G11: 1.05 | I11: 1.1 | J11: 2041 | L11: 2.03 | M11: 14.63 | N11: 5787 | P11: 5361
A12: 2005 | C12: 600 | E12: 4 | F12: 1729 | G12: 1.1 | I12: 1.15 | J12: 2188 | L12: 0.41 | M12: 55.86 | N12: 10400 | P12: 10400
A13: 2004 | C13: 2 | E13: 3 | F13: 579 | G13: 1.05 | I13: 1 | J13: 608 | L13: 14.75 | M13: 3.92 | N13: 10991 | P13: 9210
A14: 2003 | C14: 1 | E14: 2 | F14: 520 | G14: 1.05 | I14: 1 | J14: 546 | L14: 22.55 | M14: 12.26 | N14: 10620 | P14: 10500
A15: 2005 | C15: 100 | E15: 4 | F15: 1464 | G15: 1.07 | I15: 1.1 | J15: 1723 | L15: 2.83 | M15: 43.88 | N15: 8911 | P15: 8911
A16: 2004 | C16: 30 | E16: 3 | F16: 1304 | G16: 1.07 | I16: 1 | J16: 1395 | L16: 0.01 | M16: 94.01 | N16: 13648 | P16: 13648
A17: 2005 | C17: 50 | E17: 4 | F17: 1626 | G17: 1.05 | I17: 1 | J17: 1708 | L17: 0 | M17: 70.69 | N17: 31241 | P17: 30862
A18: 2004 | C18: 50 | E18: 3 | F18: 919 | G18: 1.07 | I18: 1 | J18: 983 | L18: 0 | M18: 26 | N18: 10,2809 | P18: 10,2809
A19: 2004 | C19: 100 | E19: 3 | F19: 2394 | G19: 1.07 | I19: 1.15 | J19: 2946 | L19: 0 | M19: 46.72 | N19: 10,2809 | P19: 10,2809
A20: Source: Values are derived by the Energy Information Administration, Office of Integrated Analysis and Forecasting, from analysis of reports and discussions with various sources from industry, government, and the Department of Energy National Laboratories.
A21: Table 44. Regional Multipliers for Construction of Fossil-Fueled, Nuclear, and Renewable1 Generating Technologies
A22: EMM Region NE, NY MAAC STV MAPP,
H23: ECAR, MAIN | K23: SPP
A24: 1.043 | B24: 0.996 | D24: 0.96 | H24: 1.004 | K24: 0.997
A25: EMM Region RA | B25: NWP | D25: FL | H25: CNV | K25: ERCOT
A26: 1.003 | B26: 1.026 | D26: 0.961 | H26: 1.058 | K26: 0.986
A27: 1Regional multipliers are not applied to geothermal technologies because costs are site specific.
A28: Source: Argonne National Laboratory, Cost and Performance Database for Electric Power Generating Technologies..
A29: Technological Optimism and Learning Overnight costs for each technology are calculated as a function of regional construction parameters, project contingency, and technological optimism and learning factors. For each generating technology available for new capacity in a region, the overnight cost used by the model is calculated using the base cost technological optimism and contingency factors for the technology from Table 43 and the learning parameters from Table 45.

Sheet 2002
A1: Table 38. Cost and Performance Characteristics of New Electricity Generating Technologies
A2: Total Overnight Contingency Factors Cost Overnight including Variable Heatrate Heatrate Costs Contingencies O&M4 Fixed in in Online Size Leadtimes in 2001 in 20013 ($2000 O&M4 2001 2010 Technology Years1 (mW) (Years) ($2000/kW) (2000 $/kW) mills/kWh) ($2000/kW) (Btu/kWhr) (Btu/kWr)
A3: Conventional Pulverized Coal | C3: 2005 | D3: 400 | F3: 4 | G3: 1046 | I3: 1.07 | M3: 1 | O3: 1119 | Q3: 3.38 | S3: 23.41 | T3: 9386 | V3: 9087
A4: Integrated Coal- Gasification Combined | C4: 2005 | D4: 428 | F4: 4 | G4: 1250 | I4: 1.07 | M4: 1 | O4: 1338 | Q4: 0.8 | S4: 32.67 | T4: 7869 | V4: 6968
A5: Cycle Conventional Gas/Oil Combined Cycle | C5: 2004 | D5: 250 | F5: 3 | G5: 435 | I5: 1.05 | M5: 1 | O5: 456 | Q5: 0.52 | S5: 15.61 | T5: 7618 | V5: 7000
A6: Adv Gas/Oil Combined Cycle | C6: 2004 | D6: 400 | F6: 3 | G6: 546 | I6: 1.08 | M6: 1 | O6: 590 | Q6: 0.52 | S6: 14.46 | T6: 6870 | V6: 6350
A7: Conv Combustion Turbine5 | C7: 2002 | D7: 160 | F7: 2 | G7: 323 | I7: 1.05 | M7: 1 | O7: 339 | Q7: 0.1 | S7: 6.45 | T7: 11380 | V7: 10600
A8: Adv Combustion Turbine | C8: 2003 | D8: 120 | F8: 2 | G8: 451 | I8: 1.05 | M8: 1 | O8: 474 | Q8: 0.1 | S8: 9.16 | T8: 9020 | V8: 8000
A9: Fuel Cells | C9: 2004 | D9: 10 | F9: 3 | G9: 1810 | I9: 1.05 | M9: 1.1 | O9: 2091 | Q9: 2.08 | S9: 14.98 | T9: 5744 | V9: 5361
A10: Advanced Nuclear | C10: 2005 | D10: 600 | F10: 4 | G10: 1772 | I10: 1.1 | M10: 1.1 | O10: 2144 | Q10: 0.42 | S10: 57.23 | T10: 10400 | V10: 10400
A11: Generic Distributed Generation6 - Base Generic Distributed Generation6 - Peak
A12: 2004 | H12: 2 | K12: 3 | L12: 593 | N12: 1.05 | P12: 1 | R12: 623 | U12: 15.11 | W12: 4.02 | Y12: 10991 | AA12: 9210
A13: 2003 | H13: 1 | K13: 2 | L13: 533 | N13: 1.05 | P13: 1 | R13: 559 | U13: 23.1 | W13: 12.56 | Y13: 10620 | AA13: 10500
A14: Biomass | B14: 2005 | D14: 100 | F14: 4 | G14: 1536 | J14: 1.07 | M14: 1.05 | O14: 1725 | Q14: 2.9 | S14: 44.95 | T14: 8911 | V14: 8911
A15: MSW - Landfill Gas | B15: 2004 | D15: 30 | F15: 3 | G15: 1336 | J15: 1.07 | M15: 1 | O15: 1429 | Q15: 0.01 | S15: 96.31 | T15: 13648 | V15: 13648
A16: Geothermal 7,8 | B16: 2006 | D16: 50 | F16: 4 | G16: 1663 | J16: 1.05 | M16: 1 | O16: 1746 | Q16: 0 | S16: 70.07 | T16: 32173 | V16: 32173
A17: Wind | B17: 2004 | D17: 50 | F17: 3 | G17: 918 | J17: 1.07 | M17: 1 | O17: 982 | Q17: 0 | S17: 25.54 | T17: 10280 | V17: 10280
A18: Solar Thermal8 | B18: 2004 | D18: 100 | F18: 3 | G18: 2157 | J18: 1.07 | M18: 1.1 | O18: 2539 | Q18: 0 | S18: 47.87 | T18: 10280 | V18: 10280
A19: Solar Photovoltaic8 | B19: 2003 | D19: 5 | F19: 2 | G19: 3317 | J19: 1.05 | M19: 1.1 | O19: 3831 | Q19: 0 | S19: 9.85 | T19: 10280 | V19: 10280
A20: 1Online year represents the first year that a new unit could be completed, given an order date of 2001. 2The technological optimism factor is applied to the first four units of a new, unproven design. It reflects the demonstrated tendency to underestimate actual costs for a first-of-a-kind unit. 3Overnight capital cost including contingency factors, excluding regional multipliers and learning effects. Interest charges are also excluded. These represent costs of new projects initiated in 2001. 4O&M = Operation and maintenance. 5Combustion turbine units can be built by the model prior to 2003 if necessary to meet a given region’s reserve margin. 6The costs shown here are slightly different from costs shown in Table 41 because of updated adjustments for inflation. The unit size shown here is higher than that shown in Table 41 to reflect the minimum size that can be represented meaningfully in the model. The lead times are also different from those shown in Table 41 because lead times presented here include site acquisition, site preparation, and permitting for plants that are larger in size. 7Because geothermal cost and performance characteristics are specific for each site, the table entries represent the cost of the least expensive plant that could be built in the Northwest Power Pool region, where most of the proposed sites are located. 8Capital costs for geothermal and solar technologies are net of (reduced by) the ten percent investment tax credit.
A21: Source: Values are derived by the Energy Information Administration, Office of Integrated Analysis and Forecasting, from analysis of reports and discussions with various sources from industry, government, and the Department of Energy National Laboratories.
A22: Table 39. Regional Multipliers for Construction of Fossil-Fueled, Nuclear, and Renewable1 Generating Technologies
A23: EMM Region NE, NY | E23: MAAC | I23: STV | N23: MAPP, ECAR, MAIN | S23: SPP
A24: 1.043 | E24: 0.996 | I24: 0.96 | N24: 1.004 | S24: 0.997
A25: EMM Region RA | E25: NWP | I25: FL | N25: CNV | S25: ERCOT
A26: 1.003 | E26: 1.026 | I26: 0.961 | N26: 1.058 | S26: 0.986
A27: 1Regional multipliers are not applied to geothermal technologies because costs are site specific.
A28: Source: Argonne National Laboratory, Cost and Performance Database for Electric Power Generating Technologies..
A29: Technological Optimism and Learning Overnight costs for each technology are calculated as a function of regional construction parameters, project contingency, and technological optimism and learning factors. For each generating technology available for new capacity in a region, the overnight cost used by the model is calculated using the base cost, technological optimism and contingency factors for the technology from Table 38, the regional factors from Table 39, and the learning parameters from Table 40.

Sheet 2003
A1: Total Overnight Contingency Factors Cost Overnight including Variable Heatrate Heatrate Costs2 Project Technological Contingencies O&M5 Fixed in nth-of- Online Size Leadtimes in 2002 Contingency Optimism in 20024 ($2001 O&M5 2002 a-kind Technology Years1 (mW) (Years) ($2001/kW) Factor Factor3 (2001 $/kW) mills/kWh) ($2001/kW) (Btu/kWhr) (Btu/kWr)
A2: Scrubbed Coal Newl 2006 | B2: 600 | D2: 4 | E2: 1079 | F2: 1.07 | G2: 1 | H2: 1154 | I2: 3.07 | J2: 24.52 | K2: 9000 | L2: 8600
A3: Integrated Coal- Gasification Combined 2006 | B3: 550 | D3: 4 | E3: 1277 | F3: 1.07 | G3: 1 | H3: 1367 | I3: 2.04 | J3: 33.72 | K3: 8000 | L3: 7200
A4: Cycle
A5: Conventional Gas/Oil 2005 | B5: 250 | D5: 3 | E5: 510 | F5: 1.05 | G5: 1 | H5: 536 | I5: 2.04 | J5: 12.26 | K5: 7500 | L5: 7000
A6: Adv Gas/Oil Combined 2005 | B6: 400 | D6: 3 | E6: 563 | F6: 1.08 | G6: 1 | H6: 608 | I6: 2.04 | J6: 10.22 | K6: 7000 | L6: 6350
A7: Conv Combustion Turbine6 2004 | B7: 160 | D7: 2 | E7: 389 | F7: 1.05 | G7: 1 | H7: 409 | I7: 4.09 | J7: 10.22 | K7: 10939 | L7: 10450
A8: Adv Combustion Turbine 2004 | B8: 230 | D8: 2 | E8: 439 | F8: 1.05 | G8: 1 | H8: 460 | I8: 3.07 | J8: 8.17 | K8: 9394 | L8: 8550
A9: Fuel Cells 2005 | B9: 10 | D9: 3 | E9: 1850 | F9: 1.05 | G9: 1.1 | H9: 2137 | I9: 20.43 | J9: 7.15 | K9: 7500 | L9: 6750
A10: Advanced Nuclear 2007 | B10: 1000 | D10: 5 | E10: 1750 | F10: 1.1 | G10: 1.1 | H10: 2117 | I10: 0.43 | J10: 58.48 | K10: 10400 | L10: 10400
A11: Distributed 2005 | B11: 2 | D11: 3 | E11: 766 | F11: 1.05 | G11: 1 | H11: 804 | I11: 6.13 | J11: 13.79 | K11: 9400 | L11: 8900
A12: Distributed 2004 | B12: 1 | D12: 2 | E12: 919 | F12: 1.05 | G12: 1 | H12: 965 | I12: 6.13 | J12: 13.79 | K12: 10400 | L12: 9880
A13: Biomass 2006 | B13: 100 | D13: 4 | E13: 1569 | F13: 1.07 | G13: 1.05 | H13: 1763 | I13: 2.96 | J13: 45.94 | K13: 8911 | L13: 8911
A14: MSW - Landfill Gas 2005 | B14: 30 | D14: 3 | E14: 1365 | F14: 1.07 | G14: 1 | H14: 1460 | I14: 0.01 | J14: 98.42 | K14: 13648 | L14: 13648
A15: Geothermal 7,8 2006 | B15: 50 | D15: 4 | E15: 1681 | F15: 1.05 | G15: 1 | H15: 1766 | I15: 0 | J15: 71.75 | K15: 32320 | L15: 31797
A16: Wind 2005 | B16: 50 | D16: 3 | E16: 938 | F16: 1.07 | G16: 1 | H16: 1003 | I16: 0 | J16: 26.1 | K16: 10280 | L16: 10280
... A18: Solar Photovoltaic8 2004 | B18: 5 | D18: 2 | E18: 3389 | F18: 1.05 | G18: 1.1 | H18: 3915 | I18: 0 | J18: 10.06 | K18: 10280 | L18: 10280
A19: Combined Cycle
A20: Cycle
A21: Generation - Base
A22: Generation - Peak
A23: 1Online year represents the first year that a new unit could be completed, given an order date of 2002. 2Costs reflect market status and penetration as of 2002. 3The technological optimism factor is applied to the first four units of a new, unproven design. It reflects the demonstrated tendency to underestimate actual costs for a first-of-a-kind unit. 4Overnight capital cost including contingency factors, excluding regional multipliers and learning effects. Interest charges are also excluded. These represent costs of new projects initiated in 2002. 5O&M = Operation and maintenance. 6Combustion turbine units can be built by the model prior to 2004 if necessary to meet a given region’s reserve margin. 7Because geothermal cost and performance characteristics are specific for each site, the table entries represent the cost of the least expensive plant that could be built in the Northwest Power Pool region, where most of the proposed sites are located. 8Capital costs for geothermal and solar technologies are net of (reduced by) the ten percent investment tax credit.
A24: Source: The values shown in this table are developed by the Energy Information Administration, Office of Integrated Analysis and Forecasting, from analysis of reports and discussions with various sources from industry, government, and the Department of Energy Fuel Offices and National Laboratories. They are not based on any specific technology model, but rather, are meant to represent the cost and performance of typical plants under normal operating conditions for each plant type. Key sources reviewed are listed in the ‘Notes and Sources’ section at the end of the chapter.
A25: Table 41. Regional Multipliers for Construction of Fossil-Fueled, Nuclear, and Renewable1 Generating Technologies
A26: EMM Region NE, NY MAAC STV MAPP,
G27: ECAR, MAIN | J27: SPP
A28: 1.043 | C28: 0.996 | E28: 0.96 | G28: 1.004 | J28: 0.997
A29: EMM Region RA | C29: NWP | E29: FL | G29: CNV | J29: ERCOT
A30: 1.003 | C30: 1.026 | E30: 0.961 | G30: 1.058 | J30: 0.986
A31: 1Regional multipliers are not applied to geothermal technologies because costs are site specific.
A32: Source: Argonne National Laboratory, Cost and Performance Database for Electric Power Generating Technologies..
A33: Energy Information Administration/Assumptions to the Annual Energy Outlook 2003 73
A34: Technological Optimism and Learning Overnight costs for each technology are calculated as a function of regional construction parameters, project contingency, and technological optimism and learning factors. For each generating technology available for new capacity in a region, the overnight cost used by the model is calculated using the base cost, technological optimism and contingency factors for the technology from Table 40, the regional factors from Table 41, and the learning parameters from Table 42.

Sheet 2004
A1: Table 38. Cost and Performance Characteristics of New Central Station Electricity Generating Technologies
A2: Base Contingency Factors Total Overnight Overnight Variable Heatrate Heatrate Costs Project Technological Cost O&M5 Fixed in nth-of- Online Size Leadtimes in 2003 Contingency Optimism in 20033 ($2002 O&M5 2003 a-kind Technology Year1 (mW) (Years) ($2002/kW) Factor Factor2 (2002 $/kW) mills/kWh) ($2002/kW) (Btu/kWhr) (Btu/kWr)
A3: Scrubbed Coal New | B3: 2007 | D3: 600 | E3: 4 | G3: 1091 | I3: 1.07 | K3: 1 | N3: 1168 | P3: 3.1 | R3: 24.81 | S3: 9000 | V3: 8600
A4: Integrated Coal- Gasification Combined | B4: 2007 | D4: 550 | E4: 4 | G4: 1292 | I4: 1.07 | K4: 1 | N4: 1383 | P4: 2.07 | R4: 34.11 | S4: 8000 | V4: 7200
A5: Cycle (IGCC)
A6: IGCC with Carbon Sequestration | B6: 2010 | D6: 380 | E6: 4 | G6: 1894 | I6: 1.07 | K6: 1.03 | N6: 2088 | P6: 2.53 | R6: 40.47 | S6: 9600 | V6: 7920
A7: Conv Gas/Oil Comb Cycle | B7: 2006 | D7: 250 | E7: 3 | G7: 516 | I7: 1.05 | K7: 1 | N7: 542 | P7: 2.07 | R7: 12.4 | S7: 7444 | V7: 7000
A8: Adv Gas/Oil Comb Cycle (CC) | B8: 2006 | D8: 400 | E8: 3 | G8: 569 | I8: 1.08 | K8: 1 | N8: 615 | P8: 2.07 | R8: 10.34 | S8: 6928 | V8: 6350
A9: ADV CC with Carbon | B9: 2010 | D9: 400 | E9: 3 | G9: 969 | I9: 1.08 | K9: 1.04 | N9: 1088 | P9: 2.58 | R9: 14.93 | S9: 8646 | V9: 7300
A10: Sequestration
A11: Conv Combustion Turbine5 | F11: 2005 | H11: 160 | J11: 2 | K11: 394 | M11: 1.05 | O11: 1 | Q11: 413 | T11: 4.14 | W11: 10.34 | Y11: 10878 | Z11: 10450
A12: Adv Combustion Turbine | F12: 2005 | H12: 230 | J12: 2 | K12: 444 | M12: 1.05 | O12: 1 | Q12: 466 | T12: 3.1 | W12: 8.27 | Y12: 9289 | Z12: 8550
A13: Fuel Cells | F13: 2006 | H13: 10 | J13: 3 | K13: 1872 | M13: 1.05 | O13: 1.1 | Q13: 2162 | T13: 20.67 | W13: 7.23 | Y13: 7446 | Z13: 6750
A14: Advanced Nuclear | F14: 2013 | H14: 1000 | J14: 6 | K14: 1669 | M14: 1.1 | O14: 1.05 | Q14: 1928 | T14: 0.43 | W14: 59.17 | Y14: 10400 | Z14: 10400
A15: Distributed Generation - | F15: 2006 | H15: 2 | J15: 3 | K15: 775 | M15: 1.05 | O15: 1 | Q15: 813 | T15: 6.2 | W15: 13.95 | Y15: 9400 | Z15: 8900
A16: Base
A17: Peak | AA17: 13.95 | AC17: 10400 | AE17: 9880
A18: Distributed Generation - | C18: 2005 1 2 930 1.05 1.00 977 6.20
A19: Biomass | B19: 2010 | D19: 80 | E19: 4 | G19: 1588 | I19: 1.07 | K19: 1.02 | N19: 1731 | P19: 2.96 | R19: 46.47 | S19: 8911 | U19: 8911
A20: MSW - Landfill Gas | B20: 2006 | D20: 30 | E20: 3 | G20: 1381 | I20: 1.07 | K20: 1 | N20: 1477 | P20: 0.01 | R20: 99.57 | S20: 13648 | U20: 13648
A21: Geothermal 6,7 | B21: 2007 | D21: 50 | E21: 4 | G21: 2099 | I21: 1.05 | K21: 1 | N21: 2203 | P21: 0 | R21: 79.28 | S21: 37259 | U21: 36468
A22: Wind | B22: 2006 | D22: 50 | E22: 3 | G22: 949 | I22: 1.07 | K22: 1 | N22: 1015 | P22: 0 | R22: 26.41 | S22: 10280 | U22: 10280
A23: Solar Thermal7 | B23: 2006 | D23: 100 | E23: 3 | G23: 2478 | I23: 1.07 | K23: 1.1 | N23: 2916 | P23: 0 | R23: 49.48 | S23: 10280 | U23: 10280
A24: Photovoltaic7 | B24: 2005 | D24: 5 | E24: 2 | G24: 3810 | I24: 1.05 | K24: 1.1 | N24: 4401 | P24: 0 | R24: 10.08 | S24: 10280 | U24: 10280
A25: 1Online year represents the first year that a new unit could be completed, given an order date of 2003. 2The technological optimism factor is applied to the first four units of a new, unproven design. It reflects the demonstrated tendency to underestimate actual costs for a first-of-a-kind unit. 3Overnight capital cost including contingency factors, excluding regional multipliers and learning effects. Interest charges are also excluded. These represent costs of new projects initiated in 2003. 4O&M = Operation and maintenance. 5Combustion turbine units can be built by the model prior to 2005 if necessary to meet a given region’s reserve margin. 6Because geothermal cost and performance characteristics are specific for each site, the table entries represent the cost of the least expensive plant that could be built in the Northwest Power Pool region, where most of the proposed sites are located. 7Capital costs for geothermal and solar technologies are shown before the ten percent investment tax credit is applied.
A26: Sources: The values shown in this table are developed by the Energy Information Administration, Office of Integrated Analysis and Forecasting, from analysis of reports and discussions with various sources from industry, government, and the Department of Energy Fuel Offices and National Laboratories. They are not based on any specific technology model, but rather, are meant to represent the cost and performance of typical plants under normal operating conditions for each plant type. Key sources reviewed are listed in the 'Notes and Sources' section at the end of the chapter.

Sheet 2006
A1: Table 38. Cost and Performance Characteristics of New Central Station Electricity Generating Technologies
A2: Base Contingency Factors Total Overnight Overnight Variable Heatrate Heatrate Costs Project Technological Cost O&M5 Fixed in nth-of- Online Size Leadtimes in 2005 Contingency Optimism in 20053 ($2004 O&M5 2005 a-kind Technology Year1 (mW) (Years) ($2004/kW) Factor Factor2 (2004 $/kW) mills/kWh) ($2004/kW) (Btu/kWhr) (Btu/kWr)
A3: Scrubbed Coal New7 Integrated Coal-Gasification | B3: 2009 | C3: 600 | D3: 4 | E3: 1167 | F3: 1.07 | H3: 1 | K3: 1249 | L3: 4.18 | N3: 25.07 | P3: 8844 | R3: 8600
A4: Combined Cycle (IGCC)7 2009 | F4: 550 | G4: 4 | I4: 1349 | J4: 1.07 | M4: 1 | O4: 1443 | Q4: 2.65 | T4: 35.21 | U4: 8309 | V4: 7200
A5: Sequestration | T5: 41.44 | U5: 9713 | V5: 7920
A6: IGCC with Carbon | C6: 2010 380 4 1,873 1.07 1.03 2,065 4.04
A7: Conv Gas/Oil Comb Cycle | B7: 2008 | C7: 250 | D7: 3 | E7: 556 | F7: 1.05 | H7: 1 | K7: 584 | L7: 1.88 | N7: 11.37 | P7: 7196 | R7: 6800
A8: Adv Gas/Oil Comb Cycle (CC) | B8: 2008 | C8: 400 | D8: 3 | E8: 532 | F8: 1.08 | H8: 1 | K8: 575 | L8: 1.82 | N8: 10.65 | P8: 6752 | R8: 6333
A9: ADV CC with Carbon Sequestration | B9: 2010 | C9: 400 | D9: 3 | E9: 1021 | F9: 1.08 | H9: 1.04 | K9: 1147 | L9: 2.68 | N9: 18.12 | P9: 8613 | R9: 7493
A10: Conv Combustion Turbine5 | B10: 2007 | C10: 160 | D10: 2 | E10: 388 | F10: 1.05 | H10: 1 | K10: 407 | L10: 3.25 | N10: 11.03 | P10: 10842 | R10: 10450
A11: Adv Combustion Turbine | B11: 2007 | C11: 230 | D11: 2 | E11: 367 | F11: 1.05 | H11: 1 | K11: 385 | L11: 2.89 | N11: 9.59 | P11: 9227 | R11: 8550
A12: Fuel Cells | B12: 2008 | C12: 10 | D12: 3 | E12: 3787 | F12: 1.05 | H12: 1.1 | K12: 4374 | L12: 43.64 | N12: 5.15 | P12: 7930 | R12: 6960
A13: Advanced Nuclear | B13: 2013 | C13: 1000 | D13: 6 | E13: 1744 | F13: 1.1 | H13: 1.05 | K13: 2014 | L13: 0.45 | N13: 61.82 | P13: 10400 | R13: 10400
A14: Distributed Generation -Base | B14: 2008 | C14: 2 | D14: 3 | E14: 791 | F14: 1.05 | H14: 1 | K14: 831 | L14: 6.49 | N14: 14.6 | P14: 9650 | R14: 8900
A15: Distributed Generation -Peak | B15: 2007 | C15: 1 | D15: 2 | E15: 951 | F15: 1.05 | H15: 1 | K15: 998 | L15: 6.49 | N15: 14.6 | P15: 10823 | R15: 9880
A16: Biomass | B16: 2009 | C16: 80 | D16: 4 | E16: 1659 | F16: 1.07 | H16: 1.02 | K16: 1809 | L16: 3.13 | N16: 48.56 | P16: 8911 | R16: 8911
A17: MSW - Landfill Gas | B17: 2008 | C17: 30 | D17: 3 | E17: 1443 | F17: 1.07 | H17: 1 | K17: 1544 | L17: 0.01 | N17: 104.03 | P17: 13648 | R17: 13648
A18: Geothermal 6,7 | B18: 2009 | C18: 50 | D18: 4 | E18: 2100 | F18: 1.05 | H18: 1 | K18: 2205 | L18: 0 | N18: 75 | P18: 32173 | R18: 35460
... A22: Photovoltaic7 | B22: 2007 | C22: 5 | D22: 2 | E22: 3981 | F22: 1.05 | H22: 1.1 | K22: 4598 | L22: 0 | N22: 10.64 | P22: 10280 | R22: 10280
A23: 1Online year represents the first year that a new unit could be completed, given an order date of 2005. 2The technological optimism factor is applied to the first four units of a new, unproven design, or regulatory structure. It reflects the demonstrated tendency to underestimate actual costs for a first-of-a-kind unit. 3Overnight capital cost including contingency factors, excluding regional multipliers and learning effects. Interest charges are also excluded. These represent costs of new projects initiated in 2005. 4O&M = Operations and maintenance. 5Combustion turbine units can be built by the model prior to 2007 if necessary to meet a given region’s reserve margin. 6Because geothermal and hydro cost and performance characteristics are specific for each site, the table entries represent the cost of the least expensive plant that could be built in the Northwest Power Pool region, where most of the proposed sites are located. 7Capital costs are shown before investment tax credits are applied.
A24: Sources: The values shown in this table are developed by the Energy Information Administration, Office of Integrated Analysis and Forecasting, from analysis of reports and discussions with various sources from industry, government, and the Department of Energy Fuel Offices and National Laboratories. They are not based on any specific technology model, but rather, are meant to represent the cost and performance of typical plants under normal operating conditions for each plant type. Key sources reviewed are listed in the ‘Notes and Sources’ section at the end of the chapter.

Sheet 2008
A1: Table 38. Cost and Performance Characteristics of New Central Station Electricity Generating Technologies
A2: Base Contingency Factors Total Overnight Overnight Variable Heatrate6 Heatrate Cost Project Technological Cost O&M5 Fixed in nth-of- Online Size Leadtime in 2007 Contingency Optimism in 20074 ($2006 O&M5 2007 a-kind Technology Year1 (mW) (Years) ($2006/kW) Factor2 Factor3 (2006 $/kW) mills/kWh) ($2006/kW) (Btu/kWhr) (Btu/kWr)
A3: Scrubbed Coal New7 Integrated Coal-Gasification | C3: 2011 | E3: 600 | F3: 4 | G3: 1434 | I3: 1.07 | K3: 1 | N3: 1534 | O3: 4.46 | Q3: 26.79 | R3: 9200 | T3: 8740
A4: Combined Cycle (IGCC)7 2011 | H4: 550 | J4: 4 | L4: 1657 | M4: 1.07 | P4: 1 | R4: 1773 | S4: 2.84 | U4: 37.62 | V4: 8765 | X4: 7450
A5: Sequestration | U5: 44.27 | V5: 10781 | X5: 8307
A6: IGCC with Carbon | B6: 2011 380 4 2,302 1.07 1.03 2,537 4.32
A7: Conv Gas/Oil Comb Cycle | D7: 2010 | E7: 250 | F7: 3 | G7: 683 | I7: 1.05 | K7: 1 | N7: 717 | O7: 2.01 | Q7: 12.14 | R7: 7196 | T7: 6800
A8: Adv Gas/Oil Comb Cycle (CC) | D8: 2010 | E8: 400 | F8: 3 | G8: 654 | I8: 1.08 | K8: 1 | N8: 706 | O8: 1.95 | Q8: 11.38 | R8: 6752 | T8: 6333
A9: ADV CC with Carbon Sequestration | D9: 2010 | E9: 400 | F9: 3 | G9: 1254 | I9: 1.08 | K9: 1.04 | N9: 1409 | O9: 2.86 | Q9: 19.36 | R9: 8613 | T9: 7493
A10: Conv Combustion Turbine8 | D10: 2009 | E10: 160 | F10: 2 | G10: 476 | I10: 1.05 | K10: 1 | N10: 500 | O10: 3.47 | Q10: 11.78 | R10: 10833 | T10: 10450
A11: Adv Combustion Turbine | D11: 2009 | E11: 230 | F11: 2 | G11: 450 | I11: 1.05 | K11: 1 | N11: 473 | O11: 3.08 | Q11: 10.24 | R11: 9289 | T11: 8550
A12: Fuel Cells | D12: 2010 | E12: 10 | F12: 3 | G12: 4653 | I12: 1.05 | K12: 1.1 | N12: 5374 | O12: 46.62 | Q12: 5.5 | R12: 7930 | T12: 6960
A13: Advanced Nuclear | D13: 2016 | E13: 1350 | F13: 6 | G13: 2143 | I13: 1.1 | K13: 1.05 | N13: 2475 | O13: 0.48 | Q13: 66.05 | R13: 10400 | T13: 10400
A14: Distributed Generation -Base | D14: 2009 | E14: 5 | F14: 2 | G14: 972 | I14: 1.05 | K14: 1 | N14: 1021 | O14: 6.93 | Q14: 15.59 | R14: 9200 | T14: 8900
A15: Distributed Generation -Peak | D15: 2010 | E15: 2 | F15: 3 | G15: 1168 | I15: 1.05 | K15: 1 | N15: 1227 | O15: 6.93 | Q15: 15.59 | R15: 10257 | T15: 9880
A16: Biomass | D16: 2011 | E16: 80 | F16: 4 | G16: 2490 | I16: 1.07 | K16: 1.05 | N16: 2809 | O16: 6.53 | Q16: 62.7 | R16: 8911 | T16: 8911
A17: MSW - Landfill Gas | D17: 2010 | E17: 30 | F17: 3 | G17: 1773 | I17: 1.07 | K17: 1 | N17: 1897 | O17: 0.01 | Q17: 111.15 | R17: 13648 | T17: 13648
A18: Geothermal 7,9 | D18: 2011 | E18: 50 | F18: 4 | G18: 1057 | I18: 1.05 | K18: 1 | N18: 1110 | O18: 0 | Q18: 160.18 | R18: 35376 | T18: 33729
... A23: Photovoltaic7 | D23: 2009 | E23: 5 | F23: 2 | G23: 5380 | I23: 1.05 | K23: 1 | N23: 5649 | O23: 0 | Q23: 11.37 | R23: 10022 | T23: 10022
A24: 1Online year represents the first year that a new unit could be completed, given an order date of 2007. 2A contingency allowance is defined by the American Association of Cost Engineers as the "specific provision for unforeseeable elements if costs within a defined project scope; particularly important where previous experience has shown that unforeseeable events which will increase costs are likely to occur." 3The technological optimism factor is applied to the first four units of a new, unproven design. It reflects the demonstrated tendency to underestimate actual costs for a first-of-a-kind unit. 4Overnight capital cost including contingency factors, excluding regional multipliers and learning effects. Interest charges are also excluded. These represent costs of new projects initiated in 2007. 5O&M = Operations and maintenance. 6For hydro, wind, and solar technologies, the heatrate shown represents the average heatrate for conventional thermal generation as of 2006. This is used for purposes of calculating primary energy consumption displaced for these resources, and does not imply an estimate of their actual energy conversion efficiency. 7Capital costs are shown before investment tax credits are applied. 8Combustion turbine units can be built by the model prior to 2009 if necessary to meet a given region's reserve margin. 9Because geothermal and hydro cost and performance characteristics are specific for each site, the table entries represent the cost of the least expensive plant that could be built in the Northwest Power Pool region, where most of the proposed sites are located.
A25: Sources: The values shown in this table are developed by the Energy Information Administration, Office of Integrated Analysis and Forecasting, from analysis of reports and discussions with various sources from industry, government, and the Department of Energy Fuel Offices and National Laboratories. They are not based on any specific technology model, but rather, are meant to represent the cost and performance of typical plants under normal operating conditions for each plant type. Key sources reviewed are listed in the ‘Notes and Sources’ section at the end of the chapter.

Sheet 2009
A1: Table 8.2. Cost and Performance Characteristics of New Central Station Electricity Generating Technologies
A2: Base Contingency Factors Total Overnight Overnight Variable Heatrate6 Heatrate Cost Project Technological Cost O&M5 Fixed in nth-of- Online Size Leadtime in 2008 Contingency Optimism in 20084 ($2007 O&M5 2008 a-kind Technology Year1 (mW) (Years) ($2007/kW) Factor2 Factor3 (2007 $/kW) mills/kWh) ($2007/kW) (Btu/kWhr) (Btu/kWr)
A3: Scrubbed Coal New7 Integrated Coal-Gasification | B3: 21012 | D3: 600 | E3: 4 | F3: 1923 | H3: 1.07 | I3: 1 | L3: 2058 | O3: 4.59 | P3: 27.53 | R3: 9200 | S3: 8740
A4: Combined Cycle (IGCC)7 2012 | G4: 550 | J4: 4 | K4: 2223 | M4: 1.07 | N4: 1 | Q4: 2378 | S4: 2.92 | U4: 38.67 | W4: 8765 | Y4: 7450
A5: CC with Carbon 2016 | G5: 380 | J5: 4 | K5: 3172 | M5: 1.07 | N5: 1.03 | Q5: 3496 | S5: 4.44 | U5: 46.12 | W5: 10781 | Y5: 8307
A6: IG Sequestration
A7: Conv Gas/Oil Comb Cycle | C7: 2011 | D7: 250 | E7: 3 | F7: 917 | H7: 1.05 | I7: 1 | L7: 962 | O7: 2.07 | P7: 12.48 | R7: 7196 | T7: 6800
A8: Adv Gas/Oil Comb Cycle (CC) | C8: 2011 | D8: 400 | E8: 3 | F8: 877 | H8: 1.08 | I8: 1 | L8: 948 | O8: 2 | P8: 11.7 | R8: 6752 | T8: 6333
A9: ADV CC with Carbon Sequestration | C9: 2016 | D9: 400 | E9: 3 | F9: 1683 | H9: 1.08 | I9: 1.04 | L9: 1890 | O9: 2.94 | P9: 19.9 | R9: 8613 | T9: 7493
A10: Conv Combustion Turbine8 | C10: 2010 | D10: 160 | E10: 2 | F10: 638 | H10: 1.05 | I10: 1 | L10: 670 | O10: 3.57 | P10: 12.11 | R10: 10810 | T10: 10450
A11: Adv Combustion Turbine | C11: 2010 | D11: 230 | E11: 2 | F11: 604 | H11: 1.05 | I11: 1 | L11: 634 | O11: 3.17 | P11: 10.53 | R11: 9289 | T11: 8550
A12: Fuel Cells | C12: 2011 | D12: 10 | E12: 3 | F12: 4640 | H12: 1.05 | I12: 1.1 | L12: 5360 | O12: 47.92 | P12: 5.65 | R12: 7930 | T12: 6960
A13: Advanced Nuclear | C13: 2016 | D13: 1350 | E13: 6 | F13: 2873 | H13: 1.1 | I13: 1.05 | L13: 3318 | O13: 0.49 | P13: 90.02 | R13: 10434 | T13: 10434
A14: Distributed Generation -Base | C14: 2011 | D14: 2 | E14: 3 | F14: 1305 | H14: 1.05 | I14: 1 | L14: 1370 | O14: 7.12 | P14: 16.03 | R14: 9050 | T14: 8900
A15: Distributed Generation -Peak | C15: 2010 | D15: 1 | E15: 2 | F15: 1566 | H15: 1.05 | I15: 1 | L15: 1645 | O15: 7.12 | P15: 16.03 | R15: 10069 | T15: 9880
A16: Biomass | C16: 2012 | D16: 80 | E16: 4 | F16: 3339 | H16: 1.07 | I16: 1.05 | L16: 3766 | O16: 6.71 | P16: 64.45 | R16: 9646 | T16: 7765
A17: MSW - Landfill Gas | C17: 2010 | D17: 30 | E17: 3 | F17: 2377 | H17: 1.07 | I17: 1 | L17: 2543 | O17: 0.01 | P17: 114.25 | R17: 13648 | T17: 13648
A18: Geothermal 7,9 | C18: 2010 | D18: 50 | E18: 4 | F18: 1630 | H18: 1.05 | I18: 1 | L18: 1711 | O18: 0 | P18: 164.64 | R18: 34633 | T18: 30301
... A23: Photovoltaic7 | C23: 2011 | D23: 5 | E23: 2 | F23: 5750 | H23: 1.05 | I23: 1 | L23: 6038 | O23: 0 | P23: 11.68 | R23: 9919 | T23: 9919
A24: 1Online year represents the first year that a new unit could be completed, given an order date of 2008. For wind, geothermal and landfill gas, the online year was moved earlier to acknowledge the significant market activity already occuring in anticipation of the expiration of the Production Tax Credit in 2009 for wind and 2010 for the others. 2A contingency allowance is defined by the American Association of Cost Engineers as the "specific provision for unforeseeable elements if costs within a defined project scope; particularly important where previous experience has shown that unforeseeable events which will increase costs are likely to occur." 3The technological optimism factor is applied to the first four units of a new, unproven design. It reflects the demonstrated tendency to underestimate actual costs for a first-of-a-kind unit. 4Overnight capital cost including contingency factors, excluding regional multipliers and learning effects. Interest charges are also excluded. These represent costs of new projects initiated in 2008. 5O&M = Operations and maintenance. 6For hydro, wind, and solar technologies, the heatrate shown represents the average heatrate for conventional thermal generation as of 2007. This is used for purposes of calculating primary energy consumption displaced for these resources, and does not imply an estimate of their actual energy conversion efficiency. 7Capital costs are shown before investment tax credits are applied. 8Combustion turbine units can be built by the model prior to 2010 if necessary to meet a given region’s reserve margin. 9Because geothermal and hydro cost and performance characteristics are specific for each site, the table entries represent the cost of the least expensive plant that could be built in the Northwest Power Pool region, where most of the proposed sites are located. Sources: The values shown in this table are developed by the Energy Information Administration, Office of Integrated Analysis and Forecasting, from analysis of reports and discussions with various sources from industry, government, and the Department of Energy Fuel Offices and National Laboratories. They are not based on any specific technology model, but rather, are meant to represent the cost and performance of typical plants under normal operating conditions for each plant type. Key sources reviewed are listed in the ‘Notes and Sources’ section at the end of the chapter.

Sheet 2013
A1: Table 8.2. Cost and performance characteristics of new central station electricity generating technologies
A2: Base | F2: Contingency Factors Total | K2: nth-of-a-
D3: Overnight Cost in | E3: Project | F3: Techno- | G3: Overnight Cost in | H3: Variable | I3: Fixed | J3: Heatrate6 | L3: kind
D4: Lead 2012 | E4: Contin- | F4: logical | G4: 20124 | H4: O&M5 | I4: O&M | J4: in 2012 | L4: Heatrate
C5: Online Size | D5: time (2011 $/ | E5: gency | F5: Optimism | G5: (2011 $/ | H5: (2011 $/ | I5: (2011$/ | J5: (Btu/ | L5: (Btu/
A6: Technology | C6: Year1 (mW) | D6: (years) kW) | E6: Factor2 | F6: Factor3 | G6: kW) | H6: mWh) | I6: kW) | J6: kWh) | L6: kWh)
A7: Scrubbed Coal New7 | C7: 2016 1300 | D7: 4 2,694 | E7: 1.07 | F7: 1 | G7: 2883 | H7: 4.39 | I7: 30.64 | J7: 8800 | L7: 8740
A8: Integrated Coal- Gasification Comb Cycle (IGCC)7 | C8: 2016 1200 | D8: 4 3,475 | E8: 1.07 | F8: 1 | G8: 3718 | H8: 7.09 | I8: 50.49 | J8: 8700 | L8: 7450
A9: P C | B9: ulverized Coal with arbon sequestion | C9: 2017 650 | D9: 4 4,662 | E9: 1.07 | F9: 1.03 | G9: 5138 | H9: 4.37 | I9: 65.31 | J9: 12000 | L9: 9316
A10: C C | B10: onv Gas/Oil Comb ycle | C10: 2015 620 | D10: 3 858 | E10: 1.05 | F10: 1 | G10: 901 | H10: 3.54 | I10: 12.94 | J10: 7050 | L10: 6800
A11: Adv Gas/Oil Comb Cycle (CC) | C11: 2015 400 | D11: 3 931 | E11: 1.08 | F11: 1 | G11: 1006 | H11: 3.21 | I11: 15.1 | J11: 6430 | L11: 6333
A12: Adv CC with carbon sequestration | C12: 2017 340 | D12: 3 1,833 | E12: 1.08 | F12: 1.04 | G12: 2059 | H12: 6.66 | I12: 31.23 | J12: 7525 | L12: 7493
A13: C T | B13: onv Comb urbine8 | C13: 2014 85 | D13: 2 910 | E13: 1.05 | F13: 1 | G13: 956 | H13: 15.18 | I13: 7.21 | J13: 10850 | L13: 10450
A14: Adv Comb Turbine | C14: 2014 210 | D14: 2 632 | E14: 1.05 | F14: 1 | G14: 664 | H14: 10.19 | I14: 6.92 | J14: 9750 | L14: 8550
A15: F | B15: uel Cells | C15: 2015 10 | D15: 3 6,045 | E15: 1.05 | F15: 1.1 | G15: 6982 | H15: 0 | I15: 357.47 | J15: 9500 | L15: 6960
A16: Adv Nuclear | C16: 2018 2236 | D16: 6 4,700 | E16: 1.1 | F16: 1.05 | G16: 5429 | H16: 2.1 | I16: 91.65 | J16: 10452 | L16: 10452
A17: Distributed Generation - Base | C17: 2015 2 | D17: 3 1,395 | E17: 1.05 | F17: 1 | G17: 1465 | H17: 7.62 | I17: 17.14 | J17: 9038 | L17: 8900
A18: Distributed Generation - Peak | C18: 2015 1 | D18: 2 1,675 | E18: 1.05 | F18: 1 | G18: 1759 | H18: 7.62 | I18: 17.14 | J18: 10042 | L18: 9880
A19: B | B19: iomass | C19: 2016 50 | D19: 4 3,685 | E19: 1.07 | F19: 1.02 | G19: 4041 | H19: 5.17 | I19: 103.79 | J19: 13500 | L19: 13500
A20: Geothermal7,9 | C20: 2013 50 | D20: 4 2,444 | E20: 1.05 | F20: 1 | G20: 2567 | H20: 0 | I20: 110.94 | J20: 9756 | L20: 9756
A21: MSW - Landfill Gas Hydropower9 | C21: 2013 50 2016 500 | D21: 3 7,858 4 2,179 | E21: 1.07 1.10 | F21: 1.00 1.00 | G21: 8,408 2,397 | H21: 8.51 2.60 | I21: 381.74 14.57 | J21: 13,648 9,756 | L21: 13,648 9,756
A22: Wind | C22: 2013 100 | D22: 3 2,032 | E22: 1.07 | F22: 1 | G22: 2175 | H22: 0 | I22: 38.86 | J22: 9756 | L22: 9756
A23: Wind Offshore | C23: 2016 400 | D23: 4 4,452 | E23: 1.1 | F23: 1.25 | G23: 6121 | H23: 0 | I23: 72.71 | J23: 9756 | L23: 9756
A24: So | B24: lar Thermal7 | C24: 2015 100 | D24: 3 4,653 | E24: 1.07 | F24: 1 | G24: 4979 | H24: 0 | I24: 66.09 | J24: 9756 | L24: 9756
A25: Conventional
